Workbook

Sheet Berechnung
A1: Vorname | B1: Name | C1: Unterrichtsbe-teiligung | D1: Klausur 1 | E1: Klausur 2 | F1: Note 1. Hj. | G1: Gewichtung | I1: Gesamtnote | J1: mit Zusatzleistungen | K1: In Notenskala | L1: In Punkten | M1: Ggf. Zusatzleistung 1 | N1: % | O1: Ggf. Zusatzleistung 2 | P1: % | Q1: Ggf. Zusatzleistung 3 | R1: % | X1: mdl. | Y1: schrift.
A2: Timo | B2: Bahl | C2: 13 | D2: 8 | G2: Unterrichtsbeteiligung: | H2: 0.4 | I2: =IFERROR((C2*$H$2)+((D2*$H$4)+(E2*$H$5))*$H$3,"") -> 10 | J2: =IF(AND(M2="",O2="",Q2=""), I2, (I2*(100%- (S2+T2+U2)))+(M2*S2+O2*T2+Q2*U2)) -> 10 | K2: =IF($H$11="N",VLOOKUP(I2,Schlüssel!$A$2:$B$17,2,TRUE()),"") | L2: =IFERROR(IF(F2="",IF($H$11="P",ROUND(J2,0),""),IF($H$11="P",ROUND(J2*60%+F2*40%,0),"")),"") -> 10 | S2: =IF(M2>$C2,N2,0%) -> 0 | T2: =IF(O2>$C2,P2,0%) -> 0 | U2: =IF(Q2>$C2,R2,0%) -> 0 | X2: =$H$2 -> 0.4 | Y2: =$H$3 -> 0.6
A3: Sarah | B3: Bohnsack | C3: 9 | D3: 2 | G3: Schriftliche Leistungen: | H3: =100%-H2 -> 0.6 | I3: =IFERROR((C3*$H$2)+((D3*$H$4)+(E3*$H$5))*$H$3,"") -> 4.8 | J3: =IF(AND(M3="",O3="",Q3=""), I3, (I3*(100%- (S3+T3+U3)))+(M3*S3+O3*T3+Q3*U3)) -> 4.8 | K3: =IF($H$11="N",VLOOKUP(I3,Schlüssel!$A$2:$B$17,2,TRUE()),"") | L3: =IFERROR(IF(F3="",IF($H$11="P",ROUND(J3,0),""),IF($H$11="P",ROUND(J3*60%+F3*40%,0),"")),"") -> 5 | S3: =IF(M3>$C3,N3,0%) -> 0 | T3: =IF(O3>$C3,P3,0%) -> 0 | U3: =IF(Q3>$C3,R3,0%) -> 0 | X3: =$H$2 -> 0.4 | Y3: =$H$3 -> 0.6
A4: Niklas | B4: Faust | C4: 10 | D4: 6 | G4: Klausur 1: | H4: 1 | I4: =IFERROR((C4*$H$2)+((D4*$H$4)+(E4*$H$5))*$H$3,"") -> 7.6 | J4: =IF(AND(M4="",O4="",Q4=""), I4, (I4*(100%- (S4+T4+U4)))+(M4*S4+O4*T4+Q4*U4)) -> 7.6 | K4: =IF($H$11="N",VLOOKUP(I4,Schlüssel!$A$2:$B$17,2,TRUE()),"") | L4: =IFERROR(IF(F4="",IF($H$11="P",ROUND(J4,0),""),IF($H$11="P",ROUND(J4*60%+F4*40%,0),"")),"") -> 8 | S4: =IF(M4>$C4,N4,0%) -> 0 | T4: =IF(O4>$C4,P4,0%) -> 0 | U4: =IF(Q4>$C4,R4,0%) -> 0 | X4: =$H$2 -> 0.4 | Y4: =$H$3 -> 0.6
A5: Fahrettin | B5: Gediz | C5: 12 | D5: 11 | G5: Klausur 2: | H5: =100%-H4 -> 0 | I5: =IFERROR((C5*$H$2)+((D5*$H$4)+(E5*$H$5))*$H$3,"") -> 11.4 | J5: =IF(AND(M5="",O5="",Q5=""), I5, (I5*(100%- (S5+T5+U5)))+(M5*S5+O5*T5+Q5*U5)) -> 11.4 | K5: =IF($H$11="N",VLOOKUP(I5,Schlüssel!$A$2:$B$17,2,TRUE()),"") | L5: =IFERROR(IF(F5="",IF($H$11="P",ROUND(J5,0),""),IF($H$11="P",ROUND(J5*60%+F5*40%,0),"")),"") -> 11 | S5: =IF(M5>$C5,N5,0%) -> 0 | T5: =IF(O5>$C5,P5,0%) -> 0 | U5: =IF(Q5>$C5,R5,0%) -> 0 | X5: =$H$2 -> 0.4 | Y5: =$H$3 -> 0.6
A6: Nils | B6: Heitbrink | C6: 10 | D6: 11 | I6: =IFERROR((C6*$H$2)+((D6*$H$4)+(E6*$H$5))*$H$3,"") -> 10.6 | J6: =IF(AND(M6="",O6="",Q6=""), I6, (I6*(100%- (S6+T6+U6)))+(M6*S6+O6*T6+Q6*U6)) -> 10.6 | K6: =IF($H$11="N",VLOOKUP(I6,Schlüssel!$A$2:$B$17,2,TRUE()),"") | L6: =IFERROR(IF(F6="",IF($H$11="P",ROUND(J6,0),""),IF($H$11="P",ROUND(J6*60%+F6*40%,0),"")),"") -> 11 | S6: =IF(M6>$C6,N6,0%) -> 0 | T6: =IF(O6>$C6,P6,0%) -> 0 | U6: =IF(Q6>$C6,R6,0%) -> 0 | X6: =$H$2 -> 0.4 | Y6: =$H$3 -> 0.6
A7: Dennis | B7: Kyrpychenko | C7: 14 | D7: 13 | G7: Gesamt: | H7: =H2+H3 -> 1 | I7: =IFERROR((C7*$H$2)+((D7*$H$4)+(E7*$H$5))*$H$3,"") -> 13.4 | J7: =IF(AND(M7="",O7="",Q7=""), I7, (I7*(100%- (S7+T7+U7)))+(M7*S7+O7*T7+Q7*U7)) -> 13.4 | K7: =IF($H$11="N",VLOOKUP(I7,Schlüssel!$A$2:$B$17,2,TRUE()),"") | L7: =IFERROR(IF(F7="",IF($H$11="P",ROUND(J7,0),""),IF($H$11="P",ROUND(J7*60%+F7*40%,0),"")),"") -> 13 | S7: =IF(M7>$C7,N7,0%) -> 0 | T7: =IF(O7>$C7,P7,0%) -> 0 | U7: =IF(Q7>$C7,R7,0%) -> 0 | X7: =$H$2 -> 0.4 | Y7: =$H$3 -> 0.6
A8: Finn | B8: Lenz | C8: 14 | D8: 11 | I8: =IFERROR((C8*$H$2)+((D8*$H$4)+(E8*$H$5))*$H$3,"") -> 12.2 | J8: =IF(AND(M8="",O8="",Q8=""), I8, (I8*(100%- (S8+T8+U8)))+(M8*S8+O8*T8+Q8*U8)) -> 12.2 | K8: =IF($H$11="N",VLOOKUP(I8,Schlüssel!$A$2:$B$17,2,TRUE()),"") | L8: =IFERROR(IF(F8="",IF($H$11="P",ROUND(J8,0),""),IF($H$11="P",ROUND(J8*60%+F8*40%,0),"")),"") -> 12 | S8: =IF(M8>$C8,N8,0%) -> 0 | T8: =IF(O8>$C8,P8,0%) -> 0 | U8: =IF(Q8>$C8,R8,0%) -> 0 | X8: =$H$2 -> 0.4 | Y8: =$H$3 -> 0.6
A9: Gergö | B9: Lukacs | C9: 10 | D9: 3 | I9: =IFERROR((C9*$H$2)+((D9*$H$4)+(E9*$H$5))*$H$3,"") -> 5.8 | J9: =IF(AND(M9="",O9="",Q9=""), I9, (I9*(100%- (S9+T9+U9)))+(M9*S9+O9*T9+Q9*U9)) -> 5.8 | K9: =IF($H$11="N",VLOOKUP(I9,Schlüssel!$A$2:$B$17,2,TRUE()),"") | L9: =IFERROR(IF(F9="",IF($H$11="P",ROUND(J9,0),""),IF($H$11="P",ROUND(J9*60%+F9*40%,0),"")),"") -> 6 | S9: =IF(M9>$C9,N9,0%) -> 0 | T9: =IF(O9>$C9,P9,0%) -> 0 | U9: =IF(Q9>$C9,R9,0%) -> 0 | X9: =$H$2 -> 0.4 | Y9: =$H$3 -> 0.6
A10: Dennis | B10: Noack | C10: 8 | D10: - | G10: Punkte oder Notenwerte? | I10: =IFERROR((C10*$H$2)+((D10*$H$4)+(E10*$H$5))*$H$3,"") | J10: =IF(AND(M10="",O10="",Q10=""), I10, (I10*(100%- (S10+T10+U10)))+(M10*S10+O10*T10+Q10*U10)) | K10: =IF($H$11="N",VLOOKUP(I10,Schlüssel!$A$2:$B$17,2,TRUE()),"") | L10: =IFERROR(IF(F10="",IF($H$11="P",ROUND(J10,0),""),IF($H$11="P",ROUND(J10*60%+F10*40%,0),"")),"") | S10: =IF(M10>$C10,N10,0%) -> 0 | T10: =IF(O10>$C10,P10,0%) -> 0 | U10: =IF(Q10>$C10,R10,0%) -> 0 | X10: =$H$2 -> 0.4 | Y10: =$H$3 -> 0.6
A11: Lasse | B11: Pöhls | C11: 11 | D11: 4 | G11: (P oder N) | H11: P | I11: =IFERROR((C11*$H$2)+((D11*$H$4)+(E11*$H$5))*$H$3,"") -> 6.8 | J11: =IF(AND(M11="",O11="",Q11=""), I11, (I11*(100%- (S11+T11+U11)))+(M11*S11+O11*T11+Q11*U11)) -> 6.8 | K11: =IF($H$11="N",VLOOKUP(I11,Schlüssel!$A$2:$B$17,2,TRUE()),"") | L11: =IFERROR(IF(F11="",IF($H$11="P",ROUND(J11,0),""),IF($H$11="P",ROUND(J11*60%+F11*40%,0),"")),"") -> 7 | S11: =IF(M11>$C11,N11,0%) -> 0 | T11: =IF(O11>$C11,P11,0%) -> 0 | U11: =IF(Q11>$C11,R11,0%) -> 0 | X11: =$H$2 -> 0.4 | Y11: =$H$3 -> 0.6
A12: Jerik | B12: Reddig | C12: 9 | D12: 0 | I12: =IFERROR((C12*$H$2)+((D12*$H$4)+(E12*$H$5))*$H$3,"") -> 3.6 | J12: =IF(AND(M12="",O12="",Q12=""), I12, (I12*(100%- (S12+T12+U12)))+(M12*S12+O12*T12+Q12*U12)) -> 3.6 | K12: =IF($H$11="N",VLOOKUP(I12,Schlüssel!$A$2:$B$17,2,TRUE()),"") | L12: =IFERROR(IF(F12="",IF($H$11="P",ROUND(J12,0),""),IF($H$11="P",ROUND(J12*60%+F12*40%,0),"")),"") -> 4 | S12: =IF(M12>$C12,N12,0%) -> 0 | T12: =IF(O12>$C12,P12,0%) -> 0 | U12: =IF(Q12>$C12,R12,0%) -> 0 | X12: =$H$2 -> 0.4 | Y12: =$H$3 -> 0.6
A13: Jeremy | B13: Rohwer | C13: 10 | D13: 12 | I13: =IFERROR((C13*$H$2)+((D13*$H$4)+(E13*$H$5))*$H$3,"") -> 11.2 | J13: =IF(AND(M13="",O13="",Q13=""), I13, (I13*(100%- (S13+T13+U13)))+(M13*S13+O13*T13+Q13*U13)) -> 11.2 | K13: =IF($H$11="N",VLOOKUP(I13,Schlüssel!$A$2:$B$17,2,TRUE()),"") | L13: =IFERROR(IF(F13="",IF($H$11="P",ROUND(J13,0),""),IF($H$11="P",ROUND(J13*60%+F13*40%,0),"")),"") -> 11 | S13: =IF(M13>$C13,N13,0%) -> 0 | T13: =IF(O13>$C13,P13,0%) -> 0 | U13: =IF(Q13>$C13,R13,0%) -> 0 | X13: =$H$2 -> 0.4 | Y13: =$H$3 -> 0.6
A14: Nora | B14: Schewe | C14: 13 | D14: 13 | I14: =IFERROR((C14*$H$2)+((D14*$H$4)+(E14*$H$5))*$H$3,"") -> 13 | J14: =IF(AND(M14="",O14="",Q14=""), I14, (I14*(100%- (S14+T14+U14)))+(M14*S14+O14*T14+Q14*U14)) -> 13 | K14: =IF($H$11="N",VLOOKUP(I14,Schlüssel!$A$2:$B$17,2,TRUE()),"") | L14: =IFERROR(IF(F14="",IF($H$11="P",ROUND(J14,0),""),IF($H$11="P",ROUND(J14*60%+F14*40%,0),"")),"") -> 13 | S14: =IF(M14>$C14,N14,0%) -> 0 | T14: =IF(O14>$C14,P14,0%) -> 0 | U14: =IF(Q14>$C14,R14,0%) -> 0 | X14: =$H$2 -> 0.4 | Y14: =$H$3 -> 0.6
A15: Tim | B15: Scholtz | C15: 11 | D15: 5 | I15: =IFERROR((C15*$H$2)+((D15*$H$4)+(E15*$H$5))*$H$3,"") -> 7.4 | J15: =IF(AND(M15="",O15="",Q15=""), I15, (I15*(100%- (S15+T15+U15)))+(M15*S15+O15*T15+Q15*U15)) -> 7.4 | K15: =IF($H$11="N",VLOOKUP(I15,Schlüssel!$A$2:$B$17,2,TRUE()),"") | L15: =IFERROR(IF(F15="",IF($H$11="P",ROUND(J15,0),""),IF($H$11="P",ROUND(J15*60%+F15*40%,0),"")),"") -> 7 | S15: =IF(M15>$C15,N15,0%) -> 0 | T15: =IF(O15>$C15,P15,0%) -> 0 | U15: =IF(Q15>$C15,R15,0%) -> 0 | X15: =$H$2 -> 0.4 | Y15: =$H$3 -> 0.6
A16: Alex | B16: Sejdija | C16: 14 | D16: 15 | I16: =IFERROR((C16*$H$2)+((D16*$H$4)+(E16*$H$5))*$H$3,"") -> 14.6 | J16: =IF(AND(M16="",O16="",Q16=""), I16, (I16*(100%- (S16+T16+U16)))+(M16*S16+O16*T16+Q16*U16)) -> 14.6 | K16: =IF($H$11="N",VLOOKUP(I16,Schlüssel!$A$2:$B$17,2,TRUE()),"") | L16: =IFERROR(IF(F16="",IF($H$11="P",ROUND(J16,0),""),IF($H$11="P",ROUND(J16*60%+F16*40%,0),"")),"") -> 15 | S16: =IF(M16>$C16,N16,0%) -> 0 | T16: =IF(O16>$C16,P16,0%) -> 0 | U16: =IF(Q16>$C16,R16,0%) -> 0 | X16: =$H$2 -> 0.4 | Y16: =$H$3 -> 0.6
A17: Torben | B17: Winkler | C17: 14 | D17: 12 | I17: =IFERROR((C17*$H$2)+((D17*$H$4)+(E17*$H$5))*$H$3,"") -> 12.8 | J17: =IF(AND(M17="",O17="",Q17=""), I17, (I17*(100%- (S17+T17+U17)))+(M17*S17+O17*T17+Q17*U17)) -> 12.8 | K17: =IF($H$11="N",VLOOKUP(I17,Schlüssel!$A$2:$B$17,2,TRUE()),"") | L17: =IFERROR(IF(F17="",IF($H$11="P",ROUND(J17,0),""),IF($H$11="P",ROUND(J17*60%+F17*40%,0),"")),"") -> 13 | S17: =IF(M17>$C17,N17,0%) -> 0 | T17: =IF(O17>$C17,P17,0%) -> 0 | U17: =IF(Q17>$C17,R17,0%) -> 0 | X17: =$H$2 -> 0.4 | Y17: =$H$3 -> 0.6
A18: Jonas | B18: Wittenberg | C18: 13 | D18: 11 | I18: =IFERROR((C18*$H$2)+((D18*$H$4)+(E18*$H$5))*$H$3,"") -> 11.8 | J18: =IF(AND(M18="",O18="",Q18=""), I18, (I18*(100%- (S18+T18+U18)))+(M18*S18+O18*T18+Q18*U18)) -> 11.8 | K18: =IF($H$11="N",VLOOKUP(I18,Schlüssel!$A$2:$B$17,2,TRUE()),"") | L18: =IFERROR(IF(F18="",IF($H$11="P",ROUND(J18,0),""),IF($H$11="P",ROUND(J18*60%+F18*40%,0),"")),"") -> 12 | S18: =IF(M18>$C18,N18,0%) -> 0 | T18: =IF(O18>$C18,P18,0%) -> 0 | U18: =IF(Q18>$C18,R18,0%) -> 0 | X18: =$H$2 -> 0.4 | Y18: =$H$3 -> 0.6
A19: Kjell | B19: Wolff | C19: 11 | D19: 8 | I19: =IFERROR((C19*$H$2)+((D19*$H$4)+(E19*$H$5))*$H$3,"") -> 9.2 | J19: =IF(AND(M19="",O19="",Q19=""), I19, (I19*(100%- (S19+T19+U19)))+(M19*S19+O19*T19+Q19*U19)) -> 9.2 | K19: =IF($H$11="N",VLOOKUP(I19,Schlüssel!$A$2:$B$17,2,TRUE()),"") | L19: =IFERROR(IF(F19="",IF($H$11="P",ROUND(J19,0),""),IF($H$11="P",ROUND(J19*60%+F19*40%,0),"")),"") -> 9 | S19: =IF(M19>$C19,N19,0%) -> 0 | T19: =IF(O19>$C19,P19,0%) -> 0 | U19: =IF(Q19>$C19,R19,0%) -> 0 | X19: =$H$2 -> 0.4 | Y19: =$H$3 -> 0.6
C20: 0 | D20: =Klausur1!N20 -> 0 | I20: =IFERROR((C20*$H$2)+((D20*$H$4)+(E20*$H$5))*$H$3,"") -> 0 | J20: =IF(AND(M20="",O20="",Q20=""), I20, (I20*(100%- (S20+T20+U20)))+(M20*S20+O20*T20+Q20*U20)) -> 0 | K20: =IF($H$11="N",VLOOKUP(I20,Schlüssel!$A$2:$B$17,2,TRUE()),"") | L20: =IFERROR(IF(F20="",IF($H$11="P",ROUND(J20,0),""),IF($H$11="P",ROUND(J20*60%+F20*40%,0),"")),"") -> 0 | S20: =IF(M20>$C20,N20,0%) -> 0 | T20: =IF(O20>$C20,P20,0%) -> 0 | U20: =IF(Q20>$C20,R20,0%) -> 0 | X20: =$H$2 -> 0.4 | Y20: =$H$3 -> 0.6
C21: 0 | D21: =Klausur1!N21 -> 0 | I21: =IFERROR((C21*$H$2)+((D21*$H$4)+(E21*$H$5))*$H$3,"") -> 0 | J21: =IF(AND(M21="",O21="",Q21=""), I21, (I21*(100%- (S21+T21+U21)))+(M21*S21+O21*T21+Q21*U21)) -> 0 | K21: =IF($H$11="N",VLOOKUP(I21,Schlüssel!$A$2:$B$17,2,TRUE()),"") | L21: =IFERROR(IF(F21="",IF($H$11="P",ROUND(J21,0),""),IF($H$11="P",ROUND(J21*60%+F21*40%,0),"")),"") -> 0 | S21: =IF(M21>$C21,N21,0%) -> 0 | T21: =IF(O21>$C21,P21,0%) -> 0 | U21: =IF(Q21>$C21,R21,0%) -> 0 | X21: =$H$2 -> 0.4 | Y21: =$H$3 -> 0.6
C22: 0 | D22: =Klausur1!N22 -> 0 | I22: =IFERROR((C22*$H$2)+((D22*$H$4)+(E22*$H$5))*$H$3,"") -> 0 | J22: =IF(AND(M22="",O22="",Q22=""), I22, (I22*(100%- (S22+T22+U22)))+(M22*S22+O22*T22+Q22*U22)) -> 0 | K22: =IF($H$11="N",VLOOKUP(I22,Schlüssel!$A$2:$B$17,2,TRUE()),"") | L22: =IFERROR(IF(F22="",IF($H$11="P",ROUND(J22,0),""),IF($H$11="P",ROUND(J22*60%+F22*40%,0),"")),"") -> 0 | S22: =IF(M22>$C22,N22,0%) -> 0 | T22: =IF(O22>$C22,P22,0%) -> 0 | U22: =IF(Q22>$C22,R22,0%) -> 0 | X22: =$H$2 -> 0.4 | Y22: =$H$3 -> 0.6
C23: 0 | D23: =Klausur1!N23 -> 0 | I23: =IFERROR((C23*$H$2)+((D23*$H$4)+(E23*$H$5))*$H$3,"") -> 0 | J23: =IF(AND(M23="",O23="",Q23=""), I23, (I23*(100%- (S23+T23+U23)))+(M23*S23+O23*T23+Q23*U23)) -> 0 | K23: =IF($H$11="N",VLOOKUP(I23,Schlüssel!$A$2:$B$17,2,TRUE()),"") | L23: =IFERROR(IF(F23="",IF($H$11="P",ROUND(J23,0),""),IF($H$11="P",ROUND(J23*60%+F23*40%,0),"")),"") -> 0 | S23: =IF(M23>$C23,N23,0%) -> 0 | T23: =IF(O23>$C23,P23,0%) -> 0 | U23: =IF(Q23>$C23,R23,0%) -> 0 | X23: =$H$2 -> 0.4 | Y23: =$H$3 -> 0.6
C24: 0 | D24: =Klausur1!N24 -> 0 | I24: =IFERROR((C24*$H$2)+((D24*$H$4)+(E24*$H$5))*$H$3,"") -> 0 | J24: =IF(AND(M24="",O24="",Q24=""), I24, (I24*(100%- (S24+T24+U24)))+(M24*S24+O24*T24+Q24*U24)) -> 0 | K24: =IF($H$11="N",VLOOKUP(I24,Schlüssel!$A$2:$B$17,2,TRUE()),"") | L24: =IFERROR(IF(F24="",IF($H$11="P",ROUND(J24,0),""),IF($H$11="P",ROUND(J24*60%+F24*40%,0),"")),"") -> 0 | S24: =IF(M24>$C24,N24,0%) -> 0 | T24: =IF(O24>$C24,P24,0%) -> 0 | U24: =IF(Q24>$C24,R24,0%) -> 0 | X24: =$H$2 -> 0.4 | Y24: =$H$3 -> 0.6
C25: 0 | D25: =Klausur1!N25 -> 0 | I25: =IFERROR((C25*$H$2)+((D25*$H$4)+(E25*$H$5))*$H$3,"") -> 0 | J25: =IF(AND(M25="",O25="",Q25=""), I25, (I25*(100%- (S25+T25+U25)))+(M25*S25+O25*T25+Q25*U25)) -> 0 | K25: =IF($H$11="N",VLOOKUP(I25,Schlüssel!$A$2:$B$17,2,TRUE()),"") | L25: =IFERROR(IF(F25="",IF($H$11="P",ROUND(J25,0),""),IF($H$11="P",ROUND(J25*60%+F25*40%,0),"")),"") -> 0 | S25: =IF(M25>$C25,N25,0%) -> 0 | T25: =IF(O25>$C25,P25,0%) -> 0 | U25: =IF(Q25>$C25,R25,0%) -> 0 | X25: =$H$2 -> 0.4 | Y25: =$H$3 -> 0.6
C26: 0 | D26: =Klausur1!N26 -> 0 | I26: =IFERROR((C26*$H$2)+((D26*$H$4)+(E26*$H$5))*$H$3,"") -> 0 | J26: =IF(AND(M26="",O26="",Q26=""), I26, (I26*(100%- (S26+T26+U26)))+(M26*S26+O26*T26+Q26*U26)) -> 0 | K26: =IF($H$11="N",VLOOKUP(I26,Schlüssel!$A$2:$B$17,2,TRUE()),"") | L26: =IFERROR(IF(F26="",IF($H$11="P",ROUND(J26,0),""),IF($H$11="P",ROUND(J26*60%+F26*40%,0),"")),"") -> 0 | S26: =IF(M26>$C26,N26,0%) -> 0 | T26: =IF(O26>$C26,P26,0%) -> 0 | U26: =IF(Q26>$C26,R26,0%) -> 0 | X26: =$H$2 -> 0.4 | Y26: =$H$3 -> 0.6
C27: 0 | D27: =Klausur1!N27 -> 0 | I27: =IFERROR((C27*$H$2)+((D27*$H$4)+(E27*$H$5))*$H$3,"") -> 0 | J27: =IF(AND(M27="",O27="",Q27=""), I27, (I27*(100%- (S27+T27+U27)))+(M27*S27+O27*T27+Q27*U27)) -> 0 | K27: =IF($H$11="N",VLOOKUP(I27,Schlüssel!$A$2:$B$17,2,TRUE()),"") | L27: =IFERROR(IF(F27="",IF($H$11="P",ROUND(J27,0),""),IF($H$11="P",ROUND(J27*60%+F27*40%,0),"")),"") -> 0 | S27: =IF(M27>$C27,N27,0%) -> 0 | T27: =IF(O27>$C27,P27,0%) -> 0 | U27: =IF(Q27>$C27,R27,0%) -> 0 | X27: =$H$2 -> 0.4 | Y27: =$H$3 -> 0.6
C28: 0 | D28: =Klausur1!N28 -> 0 | I28: =IFERROR((C28*$H$2)+((D28*$H$4)+(E28*$H$5))*$H$3,"") -> 0 | J28: =IF(AND(M28="",O28="",Q28=""), I28, (I28*(100%- (S28+T28+U28)))+(M28*S28+O28*T28+Q28*U28)) -> 0 | K28: =IF($H$11="N",VLOOKUP(I28,Schlüssel!$A$2:$B$17,2,TRUE()),"") | L28: =IFERROR(IF(F28="",IF($H$11="P",ROUND(J28,0),""),IF($H$11="P",ROUND(J28*60%+F28*40%,0),"")),"") -> 0 | S28: =IF(M28>$C28,N28,0%) -> 0 | T28: =IF(O28>$C28,P28,0%) -> 0 | U28: =IF(Q28>$C28,R28,0%) -> 0 | X28: =$H$2 -> 0.4 | Y28: =$H$3 -> 0.6
C29: 0 | D29: =Klausur1!N29 -> 0 | I29: =IFERROR((C29*$H$2)+((D29*$H$4)+(E29*$H$5))*$H$3,"") -> 0 | J29: =IF(AND(M29="",O29="",Q29=""), I29, (I29*(100%- (S29+T29+U29)))+(M29*S29+O29*T29+Q29*U29)) -> 0 | K29: =IF($H$11="N",VLOOKUP(I29,Schlüssel!$A$2:$B$17,2,TRUE()),"") | L29: =IFERROR(IF(F29="",IF($H$11="P",ROUND(J29,0),""),IF($H$11="P",ROUND(J29*60%+F29*40%,0),"")),"") -> 0 | S29: =IF(M29>$C29,N29,0%) -> 0 | T29: =IF(O29>$C29,P29,0%) -> 0 | U29: =IF(Q29>$C29,R29,0%) -> 0 | X29: =$H$2 -> 0.4 | Y29: =$H$3 -> 0.6
C30: 0 | D30: =Klausur1!N30 -> 0 | I30: =IFERROR((C30*$H$2)+((D30*$H$4)+(E30*$H$5))*$H$3,"") -> 0 | J30: =IF(AND(M30="",O30="",Q30=""), I30, (I30*(100%- (S30+T30+U30)))+(M30*S30+O30*T30+Q30*U30)) -> 0 | K30: =IF($H$11="N",VLOOKUP(I30,Schlüssel!$A$2:$B$17,2,TRUE()),"") | L30: =IFERROR(IF(F30="",IF($H$11="P",ROUND(J30,0),""),IF($H$11="P",ROUND(J30*60%+F30*40%,0),"")),"") -> 0 | S30: =IF(M30>$C30,N30,0%) -> 0 | T30: =IF(O30>$C30,P30,0%) -> 0 | U30: =IF(Q30>$C30,R30,0%) -> 0 | X30: =$H$2 -> 0.4 | Y30: =$H$3 -> 0.6
C31: 0 | D31: =Klausur1!N31 -> 0 | I31: =IFERROR((C31*$H$2)+((D31*$H$4)+(E31*$H$5))*$H$3,"") -> 0 | J31: =IF(AND(M31="",O31="",Q31=""), I31, (I31*(100%- (S31+T31+U31)))+(M31*S31+O31*T31+Q31*U31)) -> 0 | K31: =IF($H$11="N",VLOOKUP(I31,Schlüssel!$A$2:$B$17,2,TRUE()),"") | L31: =IFERROR(IF(F31="",IF($H$11="P",ROUND(J31,0),""),IF($H$11="P",ROUND(J31*60%+F31*40%,0),"")),"") -> 0 | S31: =IF(M31>$C31,N31,0%) -> 0 | T31: =IF(O31>$C31,P31,0%) -> 0 | U31: =IF(Q31>$C31,R31,0%) -> 0 | X31: =$H$2 -> 0.4 | Y31: =$H$3 -> 0.6
... C35: 0 | D35: =Klausur1!N35 -> 0 | I35: =IFERROR((C35*$H$2)+((D35*$H$4)+(E35*$H$5))*$H$3,"") -> 0 | J35: =IF(AND(M35="",O35="",Q35=""), I35, (I35*(100%- (S35+T35+U35)))+(M35*S35+O35*T35+Q35*U35)) -> 0 | K35: =IF($H$11="N",VLOOKUP(I35,Schlüssel!$A$2:$B$17,2,TRUE()),"") | L35: =IFERROR(IF(F35="",IF($H$11="P",ROUND(J35,0),""),IF($H$11="P",ROUND(J35*60%+F35*40%,0),"")),"") -> 0 | S35: =IF(M35>$C35,N35,0%) -> 0 | T35: =IF(O35>$C35,P35,0%) -> 0 | U35: =IF(Q35>$C35,R35,0%) -> 0 | X35: =$H$2 -> 0.4 | Y35: =$H$3 -> 0.6

Sheet Unterrichtsbeteiligung
A1: Vorname | B1: Name | C1: 45603 | D1: 45617 | E1: 45630 | Y1: Aktueller Stand | Z1: Datumsliste | AA1: Punkteliste
A2: =IF(Berechnung!A2="","",Berechnung!A2) -> Timo | B2: =IF(Berechnung!B2="","",Berechnung!B2) -> Bahl | C2: 10 | E2: 11 | Y2: =IFERROR(AVERAGE(C2:X2),"n / a") -> 10.5 | Z2: =TODAY() -> 46043 | AA2: 0
A3: =IF(Berechnung!A3="","",Berechnung!A3) -> Sarah | B3: =IF(Berechnung!B3="","",Berechnung!B3) -> Bohnsack | Y3: =IFERROR(AVERAGE(C3:X3),"n / a") -> n / a | Z3: =Z2-1 -> 46042 | AA3: 1
A4: =IF(Berechnung!A4="","",Berechnung!A4) -> Niklas | B4: =IF(Berechnung!B4="","",Berechnung!B4) -> Faust | C4: 10 | Y4: =IFERROR(AVERAGE(C4:X4),"n / a") -> 10 | Z4: =Z3-1 -> 46041 | AA4: 2
A5: =IF(Berechnung!A5="","",Berechnung!A5) -> Fahrettin | B5: =IF(Berechnung!B5="","",Berechnung!B5) -> Gediz | C5: 10 | D5: 11 | Y5: =IFERROR(AVERAGE(C5:X5),"n / a") -> 10.5 | Z5: =Z4-1 -> 46040 | AA5: 3
A6: =IF(Berechnung!A6="","",Berechnung!A6) -> Nils | B6: =IF(Berechnung!B6="","",Berechnung!B6) -> Heitbrink | C6: 14 | D6: 14 | E6: 13 | Y6: =IFERROR(AVERAGE(C6:X6),"n / a") -> 13.666667 | Z6: =Z5-1 -> 46039 | AA6: 4
A7: =IF(Berechnung!A7="","",Berechnung!A7) -> Dennis | B7: =IF(Berechnung!B7="","",Berechnung!B7) -> Kyrpychenko | C7: 11 | D7: 13 | E7: 13 | Y7: =IFERROR(AVERAGE(C7:X7),"n / a") -> 12.333333 | Z7: =Z6-1 -> 46038 | AA7: 5
A8: =IF(Berechnung!A8="","",Berechnung!A8) -> Finn | B8: =IF(Berechnung!B8="","",Berechnung!B8) -> Lenz | C8: 12 | D8: 10 | E8: 11 | Y8: =IFERROR(AVERAGE(C8:X8),"n / a") -> 11 | Z8: =Z7-1 -> 46037 | AA8: 6
A9: =IF(Berechnung!A9="","",Berechnung!A9) -> Gergö | B9: =IF(Berechnung!B9="","",Berechnung!B9) -> Lukacs | Y9: =IFERROR(AVERAGE(C9:X9),"n / a") -> n / a | Z9: =Z8-1 -> 46036 | AA9: 7
A10: =IF(Berechnung!A10="","",Berechnung!A10) -> Dennis | B10: =IF(Berechnung!B10="","",Berechnung!B10) -> Noack | C10: 14 | D10: 13 | E10: 13 | Y10: =IFERROR(AVERAGE(C10:X10),"n / a") -> 13.333333 | Z10: =Z9-1 -> 46035 | AA10: 8
A11: =IF(Berechnung!A11="","",Berechnung!A11) -> Lasse | B11: =IF(Berechnung!B11="","",Berechnung!B11) -> Pöhls | C11: 13 | D11: 13 | E11: 13 | Y11: =IFERROR(AVERAGE(C11:X11),"n / a") -> 13 | Z11: =Z10-1 -> 46034 | AA11: 9
A12: =IF(Berechnung!A12="","",Berechnung!A12) -> Jerik | B12: =IF(Berechnung!B12="","",Berechnung!B12) -> Reddig | C12: 12 | D12: 13 | E12: 12 | Y12: =IFERROR(AVERAGE(C12:X12),"n / a") -> 12.333333 | Z12: =Z11-1 -> 46033 | AA12: 10
A13: =IF(Berechnung!A13="","",Berechnung!A13) -> Jeremy | B13: =IF(Berechnung!B13="","",Berechnung!B13) -> Rohwer | Y13: =IFERROR(AVERAGE(C13:X13),"n / a") -> n / a | Z13: =Z12-1 -> 46032 | AA13: 11
A14: =IF(Berechnung!A14="","",Berechnung!A14) -> Nora | B14: =IF(Berechnung!B14="","",Berechnung!B14) -> Schewe | Y14: =IFERROR(AVERAGE(C14:X14),"n / a") -> n / a | Z14: =Z13-1 -> 46031 | AA14: 12
A15: =IF(Berechnung!A15="","",Berechnung!A15) -> Tim | B15: =IF(Berechnung!B15="","",Berechnung!B15) -> Scholtz | Y15: =IFERROR(AVERAGE(C15:X15),"n / a") -> n / a | Z15: =Z14-1 -> 46030 | AA15: 13
A16: =IF(Berechnung!A16="","",Berechnung!A16) -> Alex | B16: =IF(Berechnung!B16="","",Berechnung!B16) -> Sejdija | Y16: =IFERROR(AVERAGE(C16:X16),"n / a") -> n / a | Z16: =Z15-1 -> 46029 | AA16: 14
A17: =IF(Berechnung!A17="","",Berechnung!A17) -> Torben | B17: =IF(Berechnung!B17="","",Berechnung!B17) -> Winkler | Y17: =IFERROR(AVERAGE(C17:X17),"n / a") -> n / a | Z17: =Z16-1 -> 46028 | AA17: 15
A18: =IF(Berechnung!A18="","",Berechnung!A18) -> Jonas | B18: =IF(Berechnung!B18="","",Berechnung!B18) -> Wittenberg | Y18: =IFERROR(AVERAGE(C18:X18),"n / a") -> n / a | Z18: =Z17-1 -> 46027
A19: =IF(Berechnung!A19="","",Berechnung!A19) -> Kjell | B19: =IF(Berechnung!B19="","",Berechnung!B19) -> Wolff | Y19: =IFERROR(AVERAGE(C19:X19),"n / a") -> n / a | Z19: =Z18-1 -> 46026
A20: =IF(Berechnung!A20="","",Berechnung!A20) | B20: =IF(Berechnung!B20="","",Berechnung!B20) | Y20: =IFERROR(AVERAGE(C20:X20),"n / a") -> n / a | Z20: =Z19-1 -> 46025
A21: =IF(Berechnung!A21="","",Berechnung!A21) | B21: =IF(Berechnung!B21="","",Berechnung!B21) | Y21: =IFERROR(AVERAGE(C21:X21),"n / a") -> n / a | Z21: =Z20-1 -> 46024
A22: =IF(Berechnung!A22="","",Berechnung!A22) | B22: =IF(Berechnung!B22="","",Berechnung!B22) | Y22: =IFERROR(AVERAGE(C22:X22),"n / a") -> n / a | Z22: =Z21-1 -> 46023
A23: =IF(Berechnung!A23="","",Berechnung!A23) | B23: =IF(Berechnung!B23="","",Berechnung!B23) | Y23: =IFERROR(AVERAGE(C23:X23),"n / a") -> n / a | Z23: =Z22-1 -> 46022
A24: =IF(Berechnung!A24="","",Berechnung!A24) | B24: =IF(Berechnung!B24="","",Berechnung!B24) | Y24: =IFERROR(AVERAGE(C24:X24),"n / a") -> n / a | Z24: =Z23-1 -> 46021
A25: =IF(Berechnung!A25="","",Berechnung!A25) | B25: =IF(Berechnung!B25="","",Berechnung!B25) | Y25: =IFERROR(AVERAGE(C25:X25),"n / a") -> n / a | Z25: =Z24-1 -> 46020
A26: =IF(Berechnung!A26="","",Berechnung!A26) | B26: =IF(Berechnung!B26="","",Berechnung!B26) | Y26: =IFERROR(AVERAGE(C26:X26),"n / a") -> n / a | Z26: =Z25-1 -> 46019
A27: =IF(Berechnung!A27="","",Berechnung!A27) | B27: =IF(Berechnung!B27="","",Berechnung!B27) | Y27: =IFERROR(AVERAGE(C27:X27),"n / a") -> n / a | Z27: =Z26-1 -> 46018
A28: =IF(Berechnung!A28="","",Berechnung!A28) | B28: =IF(Berechnung!B28="","",Berechnung!B28) | Y28: =IFERROR(AVERAGE(C28:X28),"n / a") -> n / a | Z28: =Z27-1 -> 46017
A29: =IF(Berechnung!A29="","",Berechnung!A29) | B29: =IF(Berechnung!B29="","",Berechnung!B29) | Y29: =IFERROR(AVERAGE(C29:X29),"n / a") -> n / a | Z29: =Z28-1 -> 46016
... A35: =IF(Berechnung!A35="","",Berechnung!A35) | B35: =IF(Berechnung!B35="","",Berechnung!B35) | Y35: =IFERROR(AVERAGE(C35:X35),"n / a") -> n / a | Z35: =Z34-1 -> 46010
Z36: =Z35-1 -> 46009
Z37: =Z36-1 -> 46008
Z38: =Z37-1 -> 46007
Z39: =Z38-1 -> 46006
Z40: =Z39-1 -> 46005
Z41: =Z40-1 -> 46004
Z42: =Z41-1 -> 46003
Z43: =Z42-1 -> 46002
Z44: =Z43-1 -> 46001
Z45: =Z44-1 -> 46000
...

Sheet Klausur1
A1: Vorname | B1: Name | N1: Finale Note
A2: =IF(Berechnung!A2="","",Berechnung!A2) -> Timo | B2: =IF(Berechnung!B2="","",Berechnung!B2) -> Bahl
A3: =IF(Berechnung!A3="","",Berechnung!A3) -> Sarah | B3: =IF(Berechnung!B3="","",Berechnung!B3) -> Bohnsack
A4: =IF(Berechnung!A4="","",Berechnung!A4) -> Niklas | B4: =IF(Berechnung!B4="","",Berechnung!B4) -> Faust
A5: =IF(Berechnung!A5="","",Berechnung!A5) -> Fahrettin | B5: =IF(Berechnung!B5="","",Berechnung!B5) -> Gediz
A6: =IF(Berechnung!A6="","",Berechnung!A6) -> Nils | B6: =IF(Berechnung!B6="","",Berechnung!B6) -> Heitbrink
A7: =IF(Berechnung!A7="","",Berechnung!A7) -> Dennis | B7: =IF(Berechnung!B7="","",Berechnung!B7) -> Kyrpychenko
A8: =IF(Berechnung!A8="","",Berechnung!A8) -> Finn | B8: =IF(Berechnung!B8="","",Berechnung!B8) -> Lenz
A9: =IF(Berechnung!A9="","",Berechnung!A9) -> Gergö | B9: =IF(Berechnung!B9="","",Berechnung!B9) -> Lukacs
A10: =IF(Berechnung!A10="","",Berechnung!A10) -> Dennis | B10: =IF(Berechnung!B10="","",Berechnung!B10) -> Noack
A11: =IF(Berechnung!A11="","",Berechnung!A11) -> Lasse | B11: =IF(Berechnung!B11="","",Berechnung!B11) -> Pöhls
A12: =IF(Berechnung!A12="","",Berechnung!A12) -> Jerik | B12: =IF(Berechnung!B12="","",Berechnung!B12) -> Reddig
A13: =IF(Berechnung!A13="","",Berechnung!A13) -> Jeremy | B13: =IF(Berechnung!B13="","",Berechnung!B13) -> Rohwer
... A35: =IF(Berechnung!A35="","",Berechnung!A35) | B35: =IF(Berechnung!B35="","",Berechnung!B35)

Sheet Klausur1Schlüssel

Sheet Schlüssel
A1: Note als Zahl | B1: Note als Skala | C1: Punkte
A2: 0.7 | B2: 1+ | C2: 15
A3: 1 | B3: 1 | C3: 14
A4: 1.3 | B4: 1- | C4: 13
A5: 1.7 | B5: 2+ | C5: 12
A6: 2 | B6: 2 | C6: 11
A7: 2.3 | B7: 2- | C7: 10
A8: 2.7 | B8: 3+ | C8: 9
A9: 3 | B9: 3 | C9: 8
A10: 3.3 | B10: 3- | C10: 7
A11: 3.7 | B11: 4+ | C11: 6
A12: 4 | B12: 4 | C12: 5
A13: 4.3 | B13: 4- | C13: 4
A14: 4.7 | B14: 5+ | C14: 3
A15: 5 | B15: 5 | C15: 2
A16: 5.3 | B16: 5- | C16: 1
A17: 6 | B17: 6 | C17: 0
